Workbook

Sheet Cover
A1: AlgoTest · Tradesheet Formula Reference Guide · Research Analyst Edition
A2: Working Excel financial model — change sample data in Trade Data sheet and all metrics auto-recalculate
A4: COLOR CODING CONVENTION (financial modeling standard)
B5: BLUE TEXT | C5: Hardcoded input | D5: Values you enter manually. Safe to change — updates all dependent formulas.
B6: BLACK TEXT | C6: Excel formula | D6: Calculated cell. Do NOT type a value here — it will overwrite the formula.
B7: GREEN TEXT | C7: Cross-sheet formula | D7: Formula references another sheet (e.g. 'Trade Data'!J5). Click to navigate.
B8: ORANGE TEXT | C8: Key assumption | D8: Parameter that drives multiple metrics. Change carefully.
B9: YELLOW BG | C9: Editable assumption | D9: Cell is meant to be changed by the analyst for scenario analysis.
B10: LIGHT BLUE BG | C10: Input column | D10: Entire column contains hardcoded inputs (editable).
B11: GREEN BG | C11: Positive value | D11: Profit / favorable metric.
B12: RED BG | C12: Negative value | D12: Loss / unfavorable metric.
A15: SHEET GUIDE
B16: Trade Data | C16: Core data + all 26 formula columns | D16: Edit blue cells to update the entire model. All A–AA columns.
B17: Summary Dashboard | C17: Live summary metrics with formula text | D17: Column B shows the exact Excel formula; Column C calculates it live.
B18: MAE Logic | C18: Net MAE 1/2, Final MAE, Lowest NAV | D18: Worked example for all 4 MAE/MFE-derived columns across sample trades.
B19: Equity Curve | C19: Cumulative · Peak · DD · %DD steps | D19: Step-by-step walk through the first 4 trades with full formula tracing.
B20: Quick Reference | C20: One-page formula cheat sheet | D20: All 40+ formulas in a single printable view with examples.
A23: KEY FORMULA CONSTANTS (fixed across all sheets)
B24: Starting NAV | C24: 100 | D24: Equity curve baseline. All trades compound from this value.
B25: Data Range (Trade Data) | C25: Rows 5–14 | D25: 10 sample trades. Formulas use row 5 = Trade 1, row 14 = Trade 10.
B26: Days per Year | C26: 365.25 | D26: Used in CAGR and Years calculations to account for leap years.
B27: MAE/MFE Unit | C27: % of Spot | D27: All MAE and MFE values are stored as % of Entry Spot (e.g. −8.26 = −8.26%).
B28: Cumulative format | C28: #,##0.00 | D28: Two decimal places on all NAV / equity curve values.
B29: %DD format | C29: 0.00% | D29: Stored as decimal (e.g. −0.0959), displayed as −9.59% by Excel.
B30: Actual Live DD format | C30: 0.00 | D30: Stored as percentage number (e.g. −7.62), NOT a decimal fraction.

Sheet Trade Data
A1: AlgoTest · Sample Trade Data — NIFTY Short Straddle · Jan–May 2024 (10 Weekly Trades)
A2: 🔵 BLUE TEXT = Hardcoded input | ⚫ BLACK TEXT = Excel formula | ✅ GREEN TEXT = Cross-sheet link
A3: INPUT | B3: INPUT | C3: INPUT | D3: INPUT | E3: INPUT | F3: INPUT | G3: INPUT | H3: FORMULA | I3: FORMULA | J3: FORMULA | K3: FORMULA | L3: FORMULA | M3: FORMULA | N3: INPUT | O3: INPUT | P3: INPUT | Q3: INPUT | R3: FORMULA | S3: FORMULA | T3: FORMULA | U3: EQUITY CURVE | V3: EQUITY CURVE | W3: EQUITY CURVE | X3: EQUITY CURVE | Y3: EQUITY CURVE | Z3: EQUITY CURVE | AA3: EQUITY CURVE
A4: Trade # | B4: Entry Date | C4: Exit Date | D4: Entry Spot | E4: Exit Spot | F4: CE P&L (₹) | G4: PE P&L (₹) | H4: Net P&L (₹) | I4: Spot P&L (₹) | J4: % P&L | K4: Spot P&L % | L4: CE P&L % | M4: PE P&L % | N4: MAE CE % | O4: MFE CE % | P4: MAE PE % | Q4: MFE PE % | R4: Net MAE 1 | S4: Net MAE 2 | T4: Final MAE | U4: Cumulative | V4: Peak | W4: DD (pts) | X4: %DD | Y4: Lowest NAV | Z4: Actual Live DD | AA4: Spot Cum
A5: 1 | B5: 45295 | C5: 45302 | D5: 21800 | E5: 22050 | F5: -1500 | G5: 3200 | H5: =F5+G5 | I5: =E5-D5 | J5: =H5/D5*100 | K5: =I5/D5*100 | L5: =F5/D5*100 | M5: =G5/D5*100 | N5: -8.26 | O5: 1.5 | P5: -1.83 | Q5: 4.13 | R5: =N5+Q5 | S5: =O5+P5 | T5: =MIN(R5,S5) | U5: =100*(1+J5/100) | V5: =MAX(100,U5) | W5: =IF(U5<V5,U5-V5,0) | X5: =IF(U5<V5,W5/V5,0) | Y5: =U5 | Z5: =(Y5/V5-1)*100 | AA5: =100*(E5/D5)
A6: 2 | B6: 45309 | C6: 45316 | D6: 22000 | E6: 21800 | F6: 2800 | G6: -1200 | H6: =F6+G6 | I6: =E6-D6 | J6: =H6/D6*100 | K6: =I6/D6*100 | L6: =F6/D6*100 | M6: =G6/D6*100 | N6: -1.36 | O6: 5.45 | P6: -6.36 | Q6: 0.91 | R6: =N6+Q6 | S6: =O6+P6 | T6: =MIN(R6,S6) | U6: =U5*(1+J6/100) | V6: =MAX(V5,U6) | W6: =IF(U6<V6,U6-V6,0) | X6: =IF(U6<V6,W6/V6,0) | Y6: =U5*(1+T6/100) | Z6: =(Y6/V6-1)*100 | AA6: =AA5*(E6/D6)
A7: 3 | B7: 45323 | C7: 45330 | D7: 21900 | E7: 22300 | F7: -4200 | G7: 2100 | H7: =F7+G7 | I7: =E7-D7 | J7: =H7/D7*100 | K7: =I7/D7*100 | L7: =F7/D7*100 | M7: =G7/D7*100 | N7: -12.33 | O7: 0.91 | P7: -3.65 | Q7: 5.48 | R7: =N7+Q7 | S7: =O7+P7 | T7: =MIN(R7,S7) | U7: =U6*(1+J7/100) | V7: =MAX(V6,U7) | W7: =IF(U7<V7,U7-V7,0) | X7: =IF(U7<V7,W7/V7,0) | Y7: =U6*(1+T7/100) | Z7: =(Y7/V7-1)*100 | AA7: =AA6*(E7/D7)
A8: 4 | B8: 45337 | C8: 45344 | D8: 22200 | E8: 22100 | F8: 2600 | G8: 2400 | H8: =F8+G8 | I8: =E8-D8 | J8: =H8/D8*100 | K8: =I8/D8*100 | L8: =F8/D8*100 | M8: =G8/D8*100 | N8: -2.25 | O8: 5.86 | P8: -1.8 | Q8: 5.41 | R8: =N8+Q8 | S8: =O8+P8 | T8: =MIN(R8,S8) | U8: =U7*(1+J8/100) | V8: =MAX(V7,U8) | W8: =IF(U8<V8,U8-V8,0) | X8: =IF(U8<V8,W8/V8,0) | Y8: =U7*(1+T8/100) | Z8: =(Y8/V8-1)*100 | AA8: =AA7*(E8/D8)
A9: 5 | B9: 45358 | C9: 45365 | D9: 22100 | E9: 21700 | F9: 3100 | G9: -2800 | H9: =F9+G9 | I9: =E9-D9 | J9: =H9/D9*100 | K9: =I9/D9*100 | L9: =F9/D9*100 | M9: =G9/D9*100 | N9: -1.36 | O9: 6.33 | P9: -8.14 | Q9: 1.36 | R9: =N9+Q9 | S9: =O9+P9 | T9: =MIN(R9,S9) | U9: =U8*(1+J9/100) | V9: =MAX(V8,U9) | W9: =IF(U9<V9,U9-V9,0) | X9: =IF(U9<V9,W9/V9,0) | Y9: =U8*(1+T9/100) | Z9: =(Y9/V9-1)*100 | AA9: =AA8*(E9/D9)
A10: 6 | B10: 45372 | C10: 45379 | D10: 21700 | E10: 22400 | F10: -5600 | G10: 3800 | H10: =F10+G10 | I10: =E10-D10 | J10: =H10/D10*100 | K10: =I10/D10*100 | L10: =F10/D10*100 | M10: =G10/D10*100 | N10: -15.21 | O10: 1.38 | P10: -2.76 | Q10: 7.37 | R10: =N10+Q10 | S10: =O10+P10 | T10: =MIN(R10,S10) | U10: =U9*(1+J10/100) | V10: =MAX(V9,U10) | W10: =IF(U10<V10,U10-V10,0) | X10: =IF(U10<V10,W10/V10,0) | Y10: =U9*(1+T10/100) | Z10: =(Y10/V10-1)*100 | AA10: =AA9*(E10/D10)
A11: 7 | B11: 45386 | C11: 45393 | D11: 22400 | E11: 22600 | F11: -1200 | G11: 3600 | H11: =F11+G11 | I11: =E11-D11 | J11: =H11/D11*100 | K11: =I11/D11*100 | L11: =F11/D11*100 | M11: =G11/D11*100 | N11: -7.59 | O11: 1.79 | P11: -1.34 | Q11: 5.8 | R11: =N11+Q11 | S11: =O11+P11 | T11: =MIN(R11,S11) | U11: =U10*(1+J11/100) | V11: =MAX(V10,U11) | W11: =IF(U11<V11,U11-V11,0) | X11: =IF(U11<V11,W11/V11,0) | Y11: =U10*(1+T11/100) | Z11: =(Y11/V11-1)*100 | AA11: =AA10*(E11/D11)
A12: 8 | B12: 45400 | C12: 45407 | D12: 22500 | E12: 22300 | F12: 3400 | G12: 2100 | H12: =F12+G12 | I12: =E12-D12 | J12: =H12/D12*100 | K12: =I12/D12*100 | L12: =F12/D12*100 | M12: =G12/D12*100 | N12: -1.78 | O12: 7.56 | P12: -1.6 | Q12: 4.89 | R12: =N12+Q12 | S12: =O12+P12 | T12: =MIN(R12,S12) | U12: =U11*(1+J12/100) | V12: =MAX(V11,U12) | W12: =IF(U12<V12,U12-V12,0) | X12: =IF(U12<V12,W12/V12,0) | Y12: =U11*(1+T12/100) | Z12: =(Y12/V12-1)*100 | AA12: =AA11*(E12/D12)
A13: 9 | B13: 45414 | C13: 45421 | D13: 22300 | E13: 22800 | F13: -3800 | G13: 4200 | H13: =F13+G13 | I13: =E13-D13 | J13: =H13/D13*100 | K13: =I13/D13*100 | L13: =F13/D13*100 | M13: =G13/D13*100 | N13: -11.21 | O13: 1.35 | P13: -1.79 | Q13: 7.17 | R13: =N13+Q13 | S13: =O13+P13 | T13: =MIN(R13,S13) | U13: =U12*(1+J13/100) | V13: =MAX(V12,U13) | W13: =IF(U13<V13,U13-V13,0) | X13: =IF(U13<V13,W13/V13,0) | Y13: =U12*(1+T13/100) | Z13: =(Y13/V13-1)*100 | AA13: =AA12*(E13/D13)
A14: 10 | B14: 45428 | C14: 45435 | D14: 22800 | E14: 22500 | F14: 4100 | G14: 2600 | H14: =F14+G14 | I14: =E14-D14 | J14: =H14/D14*100 | K14: =I14/D14*100 | L14: =F14/D14*100 | M14: =G14/D14*100 | N14: -1.32 | O14: 8.77 | P14: -1.58 | Q14: 6.14 | R14: =N14+Q14 | S14: =O14+P14 | T14: =MIN(R14,S14) | U14: =U13*(1+J14/100) | V14: =MAX(V13,U14) | W14: =IF(U14<V14,U14-V14,0) | X14: =IF(U14<V14,W14/V14,0) | Y14: =U13*(1+T14/100) | Z14: =(Y14/V14-1)*100 | AA14: =AA13*(E14/D14)
A16: FORMULA TEMPLATES (generic row = n, previous row = n−1)
A17: =1,2,3… | B17: [date input] | C17: [date input] | D17: [spot input] | E17: [spot input] | F17: [CE P&L input] | G17: [PE P&L input] | H17: =F+G | I17: =E−D | J17: =H/D×100 | K17: =I/D×100 | L17: =F/D×100 | M17: =G/D×100 | N17: [MAE CE input] | O17: [MFE CE input] | P17: [MAE PE input] | Q17: [MFE PE input] | R17: =N+Q (CE_MAE + PE_MFE) | S17: =O+P (CE_MFE + PE_MAE) | T17: =MIN(R,S) | U17: n=1: =100×(1+J/100) | n>1: =U(n−1)×(1+J/100) | V17: n=1: =MAX(100,U) | n>1: =MAX(V(n−1),U) | W17: =IF(U<V, U−V, 0) | X17: =IF(U<V, W/V, 0) | Y17: n=1: =U | n>1: =U(n−1)×(1+T/100) | Z17: =(Y/V−1)×100 | AA17: n=1: =100×(E/D) | n>1: =AA(n−1)×(E/D)

Sheet Summary Dashboard
A1: AlgoTest · Summary Dashboard — Live Formulas (referencing 'Trade Data' sheet)
A2: Column B = exact Excel formula to type | Column C = live calculated result | Green formula text = cross-sheet reference
A4: Metric | B4: Excel Formula (type exactly as shown) | C4: Live Result | D4: What It Tells You
A5: PERFORMANCE OVERVIEW
A6: Total Trades | B6: =COUNTA('Trade Data'!H5:H14) | C6: =COUNTA('Trade Data'!H5:H14) | D6: Count of rows with a Net P&L value
A7: Win Count | B7: =COUNTIF('Trade Data'!J5:J14,">0") | C7: =COUNTIF('Trade Data'!J5:J14,">0") | D7: Trades where % P&L > 0
A8: Loss Count | B8: =COUNTIF('Trade Data'!J5:J14,"<0") | C8: =COUNTIF('Trade Data'!J5:J14,"<0") | D8: Trades where % P&L < 0
A9: Win % | B9: =COUNTIF('Trade Data'!J5:J14,">0")/COUNTA('Trade Data'!H5:H14)*100 | C9: =COUNTIF('Trade Data'!J5:J14,">0")/COUNTA('Trade Data'!H5:H14)*100 | D9: Win trades ÷ Total trades × 100
A10: Loss % | B10: =COUNTIF('Trade Data'!J5:J14,"<0")/COUNTA('Trade Data'!H5:H14)*100 | C10: =COUNTIF('Trade Data'!J5:J14,"<0")/COUNTA('Trade Data'!H5:H14)*100 | D10: Loss trades ÷ Total trades × 100
A11: Overall Profit (sum % P&L) | B11: =SUM('Trade Data'!J5:J14) | C11: =SUM('Trade Data'!J5:J14) | D11: Simple sum of all % P&L (NOT compounded)
A12: Avg Win % | B12: =AVERAGEIF('Trade Data'!J5:J14,">0",'Trade Data'!J5:J14) | C12: =AVERAGEIF('Trade Data'!J5:J14,">0",'Trade Data'!J5:J14) | D12: Average % P&L of winning trades only
A13: Avg Loss % | B13: =AVERAGEIF('Trade Data'!J5:J14,"<0",'Trade Data'!J5:J14) | C13: =AVERAGEIF('Trade Data'!J5:J14,"<0",'Trade Data'!J5:J14) | D13: Average % P&L of losing trades only
A14: Avg Net P&L per Trade (₹) | B14: =AVERAGE('Trade Data'!H5:H14) | C14: =AVERAGE('Trade Data'!H5:H14) | D14: Mean ₹ profit across all trades
A15: Expectancy Ratio | B15: =(COUNTIF('Trade Data'!J5:J14,">0")/COUNTA('Trade Data'!H5:H14)*AVERAGEIF('Trade Data'!J5:J14,">0",'Trade Data'!J5:J14))/ABS(AVERAGEIF('Trade Data'!J5:J14,"<0",'Trade Data'!J5:J14))-(1-COUNTIF('Trade Data'!J5:J14,">0")/COUNTA('Trade Data'!H5:H14)) | C15: =(COUNTIF('Trade Data'!J5:J14,">0")/COUNTA('Trade Data'!H5:H14)*AVERAGEIF('Trade Data'!J5:J14,">0",'Trade Data'!J5:J14))/ABS(AVERAGEIF('Trade Data'!J5:J14,"<0",'Trade Data'!J5:J14))-(1-COUNTIF('Trade Data'!J5:J14,">0")/COUNTA('Trade Data'!H5:H14)) | D15: =(WinRate × AvgWin%) / |AvgLoss%| − (1 − WinRate)
A16: Max Win — Single Trade (₹) | B16: =MAX('Trade Data'!H5:H14) | C16: =MAX('Trade Data'!H5:H14) | D16: Largest single trade profit in ₹
A17: Max Loss — Single Trade (₹) | B17: =MIN('Trade Data'!H5:H14) | C17: =MIN('Trade Data'!H5:H14) | D17: Largest single trade loss in ₹ | E17: =MIN('Trade Data'!B5:B14)
A18: First Entry Date | B18: =TEXT(MIN('Trade Data'!B5:B14),"DD-MMM-YYYY") | C18: =TEXT(MIN('Trade Data'!B5:B14),"DD-MMM-YYYY") | D18: Earliest trade entry date | E18: =MAX('Trade Data'!C5:C14)
A19: Last Exit Date | B19: =TEXT(MAX('Trade Data'!C5:C14),"DD-MMM-YYYY") | C19: =TEXT(MAX('Trade Data'!C5:C14),"DD-MMM-YYYY") | D19: Latest trade exit date
A20: Years in Sample | B20: =(MAX('Trade Data'!C5:C14)-MIN('Trade Data'!B5:B14))/365.25 | C20: =(MAX('Trade Data'!C5:C14)-MIN('Trade Data'!B5:B14))/365.25 | D20: (Last Exit − First Entry) ÷ 365.25
A21: Final Cumulative NAV | B21: ='Trade Data'!U14 | C21: ='Trade Data'!U14 | D21: Last row of Cumulative column (100-base NAV)
A22: CAGR — Options Strategy | B22: =('Trade Data'!U14/100)^(1/C20)-1 | C22: =('Trade Data'!U14/100)^(1/C20)-1 | D22: (Final Cum ÷ 100)^(1/Years) − 1
A23: CAGR — Spot (Buy & Hold) | B23: =('Trade Data'!AA14/100)^(1/C20)-1 | C23: =('Trade Data'!AA14/100)^(1/C20)-1 | D23: (Spot Cum ÷ 100)^(1/Years) − 1 — benchmark
A25: RISK METRICS
A26: Max Drawdown % | B26: =MIN('Trade Data'!X5:X14)*100 | C26: =MIN('Trade Data'!X5:X14)*100 | D26: Most negative %DD value × 100 (e.g. −9.59 = −9.59% from peak)
A27: Max Drawdown Period Start | B27: =TEXT(INDEX('Trade Data'!B5:B14,MATCH(MIN('Trade Data'!X5:X14),'Trade Data'!X5:X14,0)),"DD-MMM-YYYY") | C27: =TEXT(INDEX('Trade Data'!B5:B14,MATCH(MIN('Trade Data'!X5:X14),'Trade Data'!X5:X14,0)),"DD-MMM-YYYY") | D27: Entry date of the deepest drawdown trade
A28: CAR / MDD (Booked) | B28: =C22/ABS(C26/100) | C28: =C22/ABS(C26/100) | D28: CAGR ÷ |Max DD| — Calmar Ratio. >2 = excellent
A29: Total Net P&L (₹) | B29: =SUM('Trade Data'!H5:H14) | C29: =SUM('Trade Data'!H5:H14) | D29: Sum of all trade Net P&L in ₹
A30: Recovery Factor | B30: =SUM('Trade Data'!H5:H14)/ABS(MIN('Trade Data'!H5:H14)) | C30: =SUM('Trade Data'!H5:H14)/ABS(MIN('Trade Data'!H5:H14)) | D30: Total ₹ P&L ÷ |Worst single loss| (not same as DD pts)
A32: LIVE DD ANALYSIS (intra-trade risk)
A33: Actual Live DD — Minimum | B33: =MIN('Trade Data'!Z5:Z14) | C33: =MIN('Trade Data'!Z5:Z14) | D33: Worst intra-trade NAV vs Peak. More conservative than booked Max DD.
A34: Actual Live DD — Average | B34: =AVERAGE('Trade Data'!Z5:Z14) | C34: =AVERAGE('Trade Data'!Z5:Z14) | D34: Mean of Actual Live DD across all trades (typical exposure)
A35: CAR / MDD (Live) | B35: =C22/ABS(C33/100) | C35: =C22/ABS(C33/100) | D35: CAGR ÷ |Live DD min| — more conservative than Booked CAR/MDD
A37: OUTLIER ANALYSIS (impact of exceptional trades)
A38: +ve Outlier 1 (best trade % P&L) | B38: =LARGE('Trade Data'!J5:J14,1) | C38: =LARGE('Trade Data'!J5:J14,1) | D38: Single best trade. LARGE({J},1) = 1st largest.
A39: +ve Outlier 2 (sum of top 2 trades) | B39: =LARGE('Trade Data'!J5:J14,1)+LARGE('Trade Data'!J5:J14,2) | C39: =LARGE('Trade Data'!J5:J14,1)+LARGE('Trade Data'!J5:J14,2) | D39: Combined impact of the 2 best trades.
A40: +ve Outlier 3 (sum of top 3 trades) | B40: =LARGE('Trade Data'!J5:J14,1)+LARGE('Trade Data'!J5:J14,2)+LARGE('Trade Data'!J5:J14,3) | C40: =LARGE('Trade Data'!J5:J14,1)+LARGE('Trade Data'!J5:J14,2)+LARGE('Trade Data'!J5:J14,3) | D40: Combined impact of the 3 best trades.
A41: −ve Outlier 1 (worst trade % P&L) | B41: =SMALL('Trade Data'!J5:J14,1) | C41: =SMALL('Trade Data'!J5:J14,1) | D41: Single worst trade. SMALL({J},1) = 1st smallest.
A42: −ve Outlier 2 (sum of bottom 2 trades) | B42: =SMALL('Trade Data'!J5:J14,1)+SMALL('Trade Data'!J5:J14,2) | C42: =SMALL('Trade Data'!J5:J14,1)+SMALL('Trade Data'!J5:J14,2) | D42: Combined impact of the 2 worst trades.
A43: −ve Outlier 3 (sum of bottom 3 trades) | B43: =SMALL('Trade Data'!J5:J14,1)+SMALL('Trade Data'!J5:J14,2)+SMALL('Trade Data'!J5:J14,3) | C43: =SMALL('Trade Data'!J5:J14,1)+SMALL('Trade Data'!J5:J14,2)+SMALL('Trade Data'!J5:J14,3) | D43: Combined impact of the 3 worst trades.
A44: P&L Without Outlier 1 (remove top + bottom 1) | B44: =SUM('Trade Data'!J5:J14)-LARGE('Trade Data'!J5:J14,1)-SMALL('Trade Data'!J5:J14,1) | C44: =SUM('Trade Data'!J5:J14)-LARGE('Trade Data'!J5:J14,1)-SMALL('Trade Data'!J5:J14,1) | D44: Total P&L minus best AND worst trade.
...

Sheet MAE Logic
A1: MAE / MFE → Net MAE 1 / 2 → Final MAE → Lowest NAV → Actual Live DD | Full Derivation
A2: MAE = Max Adverse Excursion | MFE = Max Favorable Excursion | Both stored as % of Entry Spot (4dp) | Negative % = adverse move | Positive % = favorable move
A4: Column | B4: Trade 1 | C4: Trade 3 | D4: Trade 6 | E4: Trade 8 | F4: Excel Formula | G4: Why This Value? | H4: Interpretation | I4: Notes
A5: MAE CE % (adverse excursion) | B5: ='Trade Data'!N5 | C5: ='Trade Data'!N7 | D5: ='Trade Data'!N10 | E5: ='Trade Data'!N12 | F5: Input — from engine (per-leg scan) | G5: Engine scans every 1-min price. For a short CE, price rising is adverse → MAE is negative. | H5: Negative = CE went against you. −12.33 means CE premium rose by 12.33% of spot intra-day. | I5: Always ≤ 0 for a short leg. 0 means premium never rose above entry.
A6: MFE CE % (favorable excursion) | B6: ='Trade Data'!O5 | C6: ='Trade Data'!O7 | D6: ='Trade Data'!O10 | E6: ='Trade Data'!O12 | F6: Input — from engine | G6: For a short CE, price falling is favorable → MFE is positive. | H6: Positive = CE moved in your favour. +5.86 means CE dropped by 5.86% of spot at its best. | I6: Always ≥ 0 for a short leg.
A7: MAE PE % (adverse excursion) | B7: ='Trade Data'!P5 | C7: ='Trade Data'!P7 | D7: ='Trade Data'!P10 | E7: ='Trade Data'!P12 | F7: Input — from engine | G7: For a short PE, price falling is adverse → MAE is negative. | H7: Negative = PE went against you. | I7: Symmetric to CE MAE but for PE leg.
A8: MFE PE % (favorable excursion) | B8: ='Trade Data'!Q5 | C8: ='Trade Data'!Q7 | D8: ='Trade Data'!Q10 | E8: ='Trade Data'!Q12 | F8: Input — from engine | G8: For a short PE, price rising is favorable → MFE is positive. | H8: Positive = PE moved in your favour.
A9: Net MAE 1 =CE_MAE + PE_MFE | B9: ='Trade Data'!R5 | C9: ='Trade Data'!R7 | D9: ='Trade Data'!R10 | E9: ='Trade Data'!R12 | F9: =N+Q (CE MAE + PE MFE) | G9: Scenario 1: CE is at its WORST while PE is at its BEST. Assumes adverse moves are NOT simultaneous. | H9: Most negative = CE and PE moved against each other maximally. This is the 'split-risk' scenario. | I9: For a straddle, if CE is worst when market moves UP, PE MFE partly offsets it.
A10: Net MAE 2 =CE_MFE + PE_MAE | B10: ='Trade Data'!S5 | C10: ='Trade Data'!S7 | D10: ='Trade Data'!S10 | E10: ='Trade Data'!S12 | F10: =O+P (CE MFE + PE MAE) | G10: Scenario 2: CE is at its BEST while PE is at its WORST. Opposite of Scenario 1. | H10: Captures the downside move scenario where PE gets crushed while CE is fine.
A11: Final MAE =MIN(NM1, NM2) | B11: ='Trade Data'!T5 | C11: ='Trade Data'!T7 | D11: ='Trade Data'!T10 | E11: ='Trade Data'!T12 | F11: =MIN(R,S) worst of two scenarios | G11: Takes the MORE CONSERVATIVE of Net MAE 1 and Net MAE 2. This is the best estimate of real live drawdown. | H11: Used as input to Lowest NAV. Negative = NAV dipped this many % from entry NAV. Positive = position was always profitable. | I11: If Final MAE > 0, the strategy was always in profit intra-day → very favorable.
A12: Lowest NAV (Trade 1: =Cum) (Trade N: =Prev×(1+T%)) | B12: ='Trade Data'!Y5 | C12: ='Trade Data'!Y7 | D12: ='Trade Data'!Y10 | E12: ='Trade Data'!Y12 | F12: Trade 1: =U5 Trade N: =U(n-1)*(1+T/100) | G12: Projects the LOWEST the portfolio NAV would reach during the trade window, using Final MAE as the % dip from the prior NAV. | H12: 100-base value. If Trade 1 cumulative = 107.80, Lowest NAV of Trade 2 = 107.80 × (1 + Final MAE). | I12: This is NOT the booked exit — it is the worst intra-trade estimate.
A13: Actual Live DD =(Lowest NAV/Peak−1)×100 | B13: ='Trade Data'!Z5 | C13: ='Trade Data'!Z7 | D13: ='Trade Data'!Z10 | E13: ='Trade Data'!Z12 | F13: =(Y/V−1)*100 | G13: How deep the NAV went vs the running peak DURING the trade. More conservative than booked %DD. | H13: Negative % = how far below peak the portfolio dipped live. E.g. −7.62 means at worst, NAV was 7.62% below its peak. | I13: Lower (more negative) = higher live risk. Used for CAR/MDD Live.

Sheet Equity Curve
A1: Equity Curve — Step-by-Step Walkthrough (Cumulative NAV · Peak · DD · %DD · Lowest NAV · Actual Live DD)
A2: Starting NAV = 100. Cumulative compounds each trade. Peak is a running maximum. Drawdown = how far below the peak.
A4: Trade # | B4: % P&L (input) | C4: Cumulative (U) | D4: Peak (V) | E4: DD pts (W) | F4: %DD (X) | G4: Final MAE (T) | H4: Lowest NAV (Y) | I4: Actual Live DD (Z) | J4: Formula Applied
A5: 1 | B5: ='Trade Data'!J5 | C5: =100*(1+'Trade Data'!J5/100) | D5: =MAX(100,C5) | E5: =IF(C5<D5,C5-D5,0) | F5: =IF(C5<D5,E5/D5,0) | G5: ='Trade Data'!T5 | H5: =C5 | I5: =(H5/D5-1)*100 | J5: Trade 1: Cum starts at 100. Peak = MAX(100, Cum). Lowest NAV = Cum (no prior trade).
A6: 2 | B6: ='Trade Data'!J6 | C6: =C5*(1+'Trade Data'!J6/100) | D6: =MAX(D5,C6) | E6: =IF(C6<D6,C6-D6,0) | F6: =IF(C6<D6,E6/D6,0) | G6: ='Trade Data'!T6 | H6: =C5*(1+G6/100) | I6: =(H6/D6-1)*100 | J6: Trade 2: Cum = prior Cum × growth. Lowest NAV = prior Cum × (1 + Final MAE %).
A7: 3 | B7: ='Trade Data'!J7 | C7: =C6*(1+'Trade Data'!J7/100) | D7: =MAX(D6,C7) | E7: =IF(C7<D7,C7-D7,0) | F7: =IF(C7<D7,E7/D7,0) | G7: ='Trade Data'!T7 | H7: =C6*(1+G7/100) | I7: =(H7/D7-1)*100 | J7: Trade 3 is a LOSS → Cum < Peak → DD and %DD become negative. Peak stays at prior high.
A8: 4 | B8: ='Trade Data'!J8 | C8: =C7*(1+'Trade Data'!J8/100) | D8: =MAX(D7,C8) | E8: =IF(C8<D8,C8-D8,0) | F8: =IF(C8<D8,E8/D8,0) | G8: ='Trade Data'!T8 | H8: =C7*(1+G8/100) | I8: =(H8/D8-1)*100 | J8: Trade 4: Strong win. New equity high → Peak updates → DD resets to 0.
A11: KEY FORMULAS (reference row n, previous row n−1)
A12: Cumulative (n=1) | B12: =100 × (1 + %P&L/100) | C12: Starts at 100. Each trade multiplies the running NAV.
A13: Cumulative (n>1) | B13: =Cum(n−1) × (1 + %P&L/100) | C13: Compounded: a +5% trade on NAV 107.80 → 107.80 × 1.05 = 113.19
A14: Peak (n=1) | B14: =MAX(100, Cum) | C14: First trade: peak is max of starting 100 and post-trade NAV.
A15: Peak (n>1) | B15: =MAX(Peak(n−1), Cum) | C15: Running maximum — never decreases. New high → Peak = Cum.
A16: DD Points | B16: =IF(Cum < Peak, Cum−Peak, 0) | C16: Zero at equity highs. Negative below peak.
A17: %DD | B17: =IF(Cum < Peak, DD/Peak, 0) | C17: Fraction of peak lost. Format as 0.00% to display correctly.
A18: Lowest NAV (n=1) | B18: =Cum | C18: First trade: we assume no dip below cumulative.
A19: Lowest NAV (n>1) | B19: =Cum(n−1) × (1 + FinalMAE/100) | C19: Where FinalMAE is already in % (e.g. −4.13 = −4.13%).
A20: Actual Live DD | B20: =(Lowest NAV / Peak − 1) × 100 | C20: Negative % = how deep below peak the portfolio dipped intra-trade.
A21: Spot Cumulative (n=1) | B21: =100 × (Exit Spot / Entry Spot) | C21: Tracks what a buy-and-hold investor would have.
A22: Spot Cumulative (n>1) | B22: =SpotCum(n−1) × (Exit Spot / Entry Spot) | C22: Compounded across all trade windows.
A23: CAGR Options | B23: =(Final Cum / 100)^(1/Years) − 1 | C23: Years = (Last Exit − First Entry) / 365.25. Result is a decimal — format as %.

Sheet Quick Reference
A1: AlgoTest · Formula Cheat Sheet — All Metrics in One View
A2: Blue text = input · Green text = Excel formula · All formulas assume: data in rows 5:14, columns as per Trade Data sheet
A4: Metric / Column | B4: Excel Formula (generic row = n) | C4: Example Result | D4: Category
A5: TRADE DATA COLUMNS
A6: Net P&L (₹) | B6: =F+G (CE P&L + PE P&L) | C6: ₹1,700 | D6: P&L
A7: Spot P&L (₹) | B7: =E−D (Exit Spot − Entry Spot) | C7: ₹250 | D7: Spot
A8: % P&L | B8: =H/D*100 (Net P&L ÷ Entry Spot × 100) | C8: +7.7982 | D8: P&L
A9: Spot P&L % | B9: =I/D*100 (Spot P&L ÷ Entry Spot × 100) | C9: +1.1468 | D9: Spot
A10: CE P&L % | B10: =F/D*100 | C10: −6.8807 | D10: P&L
A11: PE P&L % | B11: =G/D*100 | C11: +14.6789 | D11: P&L
A12: Net MAE 1 | B12: =N+Q (CE_MAE% + PE_MFE%) | C12: −4.1300 | D12: MAE
A13: Net MAE 2 | B13: =O+P (CE_MFE% + PE_MAE%) | C13: −0.3300 | D13: MAE
A14: Final MAE | B14: =MIN(R,S) → worst scenario | C14: −4.1300 | D14: MAE
A15: Cumulative NAV (n=1) | B15: =100*(1+J/100) | C15: 107.80 | D15: NAV
A16: Cumulative NAV (n>1) | B16: =U(n−1)*(1+J/100) | C16: 115.63 | D16: NAV
A17: Peak NAV (n=1) | B17: =MAX(100,U) | C17: 107.80 | D17: NAV
A18: Peak NAV (n>1) | B18: =MAX(V(n−1),U) | C18: 115.63 | D18: NAV
A19: DD Points | B19: =IF(U<V, U−V, 0) | C19: −11.09 | D19: DD
A20: %DD | B20: =IF(U<V, W/V, 0) → format as 0.00% | C20: −9.59% | D20: DD
A21: Lowest NAV (n=1) | B21: =U | C21: 107.80 | D21: LiveDD
A22: Lowest NAV (n>1) | B22: =U(n−1)*(1+T/100) | C22: 106.82 | D22: LiveDD
A23: Actual Live DD | B23: =(Y/V−1)*100 | C23: −7.62 | D23: LiveDD
A24: Spot Cumulative (n=1) | B24: =100*(E/D) | C24: 101.15 | D24: Spot
A25: Spot Cumulative (n>1) | B25: =AA(n−1)*(E/D) | C25: 100.24 | D25: Spot
A26: SUMMARY METRICS
A27: Total Trades | B27: =COUNTA(H5:H14) | C27: 10 | D27: Summary
A28: Win % | B28: =COUNTIF(J5:J14,">0")/COUNTA(H5:H14)*100 | C28: 80.00 | D28: Summary
A29: Loss % | B29: =COUNTIF(J5:J14,"<0")/COUNTA(H5:H14)*100 | C29: 20.00 | D29: Summary
A30: Overall Profit | B30: =SUM(J5:J14) | C30: +96.39 | D30: Summary
A31: Avg Win % | B31: =AVERAGEIF(J5:J14,">0",J5:J14) | C31: +11.50 | D31: Summary
A32: Avg Loss % | B32: =AVERAGEIF(J5:J14,"<0",J5:J14) | C32: −8.94 | D32: Summary
A33: Expectancy Ratio | B33: =(COUNTIF(J,">0")/COUNTA(H)*AVERAGEIF(J,">0",J))/ABS(AVERAGEIF(J,"<0",J))−(1−COUNTIF(J,">0")/COUNTA(H)) | C33: +1.793 | D33: Summary
A34: CAGR Options | B34: =(U_last/100)^(1/Years)−1 format as 0.00% | C34: +123.4% | D34: CAGR
A35: CAGR Spot | B35: =(AA_last/100)^(1/Years)−1 format as 0.00% | C35: +1.2% | D35: CAGR
A36: Years | B36: =(MAX(C5:C14)−MIN(B5:B14))/365.25 | C36: 0.38 | D36: CAGR
A37: Max Drawdown % | B37: =MIN(X5:X14)*100 | C37: −9.59 | D37: Risk
A38: CAR/MDD (Booked) | B38: =CAGR_pct/ABS(MaxDD_pct) | C38: 12.88 | D38: Risk
A39: CAR/MDD (Live) | B39: =CAGR_pct/ABS(LiveDD_min/100) | C39: varies | D39: Risk
A40: Recovery Factor | B40: =SUM(H5:H14)/ABS(MIN(H5:H14)) | C40: 7.42 | D40: Risk
A41: OUTLIER ANALYSIS
...
